<?xml version="1.0" ?>
<sdf version="1.6">
  <model name="lazDar">
    <link name="laz_base">
      <pose>0 0 0 0 0 0</pose>
      <visual name="visual">
        <geometry>
          <cylinder>
            <radius>0.05</radius>
            <length>0.05</length>
          </cylinder>
        </geometry>
        <material>
          <script>
            <uri>file://media/materials/scripts/gazebo.material</uri>
            <name>Gazebo/Grey</name>
          </script>
        </material>
      </visual>
      <collision name="collision">
        <geometry>
          <cylinder>
            <radius>0.05</radius>
            <length>0.05</length>
          </cylinder>
        </geometry>
      </collision>
      <inertial>
        <mass>0.1</mass>
        <inertia>
          <ixx>8.333333333333334e-05</ixx>
          <ixy>0</ixy>
          <ixz>0</ixz>
          <iyy>8.333333333333334e-05</iyy>
          <iyz>0</iyz>
          <izz>0.00016666666666666666</izz>
        </inertia>
      </inertial>
    </link>
    <link name="laz_rot">
      <pose>0 0 0 0 0 0</pose>
      <visual name="visual">
        <geometry>
          <cylinder>
            <radius>0.04</radius>
            <length>0.1</length>
          </cylinder>
        </geometry>
        <material>
          <script>
            <uri>file://media/materials/scripts/gazebo.material</uri>
            <name>Gazebo/RedGlow</name>
          </script>
        </material>
      </visual>
      <collision name="collision">
        <geometry>
          <cylinder>
            <radius>0.04</radius>
            <length>0.1</length>
          </cylinder>
        </geometry>
      </collision>
      <inertial>
        <mass>0.1</mass>
        <inertia>
          <ixx>0.0003466666666666667</ixx>
          <ixy>0</ixy>
          <ixz>0</ixz>
          <iyy>0.0003466666666666667</iyy>
          <iyz>0</iyz>
          <izz>0.0006933333333333334</izz>
        </inertia>
      </inertial>
    </link>
    <joint name="lazRot" type="continuous">
      <parent>laz_base</parent>
      <child>laz_rot</child>
      <axis>
        <xyz>0 0 1</xyz>
      </axis>
      <origin>
        <xyz>0 0 0.025</xyz>
      </origin>
      <dynamics>
        <friction>
          <ode>
            <mu>0.1</mu>
          </ode>
        </friction>
      </dynamics>
    </joint>
  </model>
</sdf>
